Workbook

Sheet QT01BM01..
C1: BẢNG TỔNG HỢP MÃ NGUỒN PHÁT THẢI VÀ LOẠI BỎ KHÍ NHÀ KÍNH NĂM: 2024 | F1: PHỤ LỤC 2 GHG/QT01/BM01
A2: STT | B2: Mã nguồn Phát thải, loại bảo KNK | C2: Nguồn phát thải/ Loại bỏ KNK | D2: Khí nhà kính | E2: Tần suất xuất hiện | F2: Hạng mục kiểm kê theo NĐ06/NĐ-CP
A3: I | B3: Cat 1 | C3: Phát thải và loại bỏ KNK trực tiếp
A4: 1 | B4: 1.1 | C4: Đốt tĩnh
A5: =+A4+1 -> 2 | B5: 1.1.1 | C5: DO | D5: CO2, CH4 và N2O | E5: Thường xuyên | F5: x
A6: =+A5+1 -> 3 | B6: 1.1.2 | C6: LPG sản xuất | D6: CO2, CH4 và N2O | E6: Thường xuyên | F6: x
A7: =+A6+1 -> 4 | B7: 1.1.3 | C7: LPG nhà bếp | D7: CO2, CH4 và N2O | E7: Thường xuyên | F7: x
A8: =+A7+1 -> 5 | B8: 1.1.4 | C8: Methanol | D8: CO2 | E8: Thường xuyên | F8: x
A9: =+A8+1 -> 6 | B9: 1.1.5 | C9: Xăng | D9: CO2, CH4 và N2O | E9: Thường xuyên | F9: x
A10: =+A9+1 -> 7 | B10: 1.1.6 | C10: Dầu hỏa | D10: CO2, CH4 và N2O | E10: Thường xuyên | F10: x
A11: =+A10+1 -> 8 | B11: 1.1.7 | C11: Nước thủy tinh (Silicate) | D11: CO2 | E11: Thường xuyên | F11: x
A12: =+A11+1 -> 9 | B12: 1.1.8 | C12: Sơn khuôn | D12: CO2 | E12: Thường xuyên | F12: x
A13: =+A12+1 -> 10 | B13: 1.1.9 | C13: Sơn khuôn - Sepanol | D13: CO2 | E13: Thường xuyên | F13: x
A14: =+A13+1 -> 11 | B14: 1.1.10 | C14: Cồn công nghiệp C2H5OH | D14: CO2 | E14: Thường xuyên | F14: x
A15: =+A14+1 -> 12 | B15: 1.1.11 | C15: CO2 sử dụng cho kết dính thao | D15: CO2 | E15: Thường xuyên | F15: x
A16: =+A15+1 -> 13 | B16: 1.2 | C16: Đốt động off-road (Xe vận chuyển nội bộ trong Nhà máy - Không đăng ký biển kiểm soát)
A17: =+A16+1 -> 14 | B17: 1.2.1 | C17: DO | D17: CO2, CH4, N2O | E17: Thường xuyên | F17: x
A18: =+A17+1 -> 15 | B18: 1.2.2 | C18: Xăng | D18: CO2, CH4, N2O | E18: Thường xuyên | F18: x
A19: 16 | B19: 1.3 | C19: Đốt động on-road (Xe vận tải, vận chuyển ngoài đường - Có đăng ký biển kiểm soát) và phát thải phát tán khác
A20: =+A19+1 -> 17 | B20: 1.3.1 | C20: DO | D20: CO2, CH4, N2O | E20: Thường xuyên | F20: x
A21: =+A20+1 -> 18 | B21: 1.3.2 | C21: Xăng | D21: CO2, CH4, N2O | E21: Thường xuyên | F21: x
A22: =+A21+1 -> 19 | B22: 1.4 | C22: CO2 sử dụng cho bình cứu hỏa, diễn tập PCCC | D22: CO2 | E22: Thỉnh thoảng | F22: x
A23: =+A22+1 -> 20 | B23: 1.5 | C23: Môi chất lạnh | D23: R22, R32, R410A, R407C,… | E23: Thường xuyên | F23: x
A24: =+A23+1 -> 21 | B24: 1.6 | C24: Xử lý nước thải tập trung | D24: CO2, CH4, N2O | E24: Thường xuyên | F24: x
A25: =+A24+1 -> 22 | B25: 1.7 | C25: Số lượng phân bón sử dụng cho cây | D25: CO2, CH4, N2O | E25: Thỉnh thoảng | F25: x
A26: 23 | B26: 1.8 | C26: Cây xanh (nguồn hấp thụ) | D26: CO2 | E26: Thường xuyên | F26: x
A27: II | B27: Cat 2 | C27: Phát thải gián tiếp từ năng lượng nhập khẩu
A28: 24 | B28: 2.1 | C28: Điện lưới mua về sử dụng tại DISOCO | D28: CO2e | E28: Thường xuyên | F28: x
A29: III | B29: Cat 3 | C29: Phát thải gián tiếp từ hoạt động vận tải
A30: 25 | B30: 3.1 | C30: Nhiên liệu sử dụng cho hoạt động thuê xe đưa đón cán bộ công nhân viên (DO, xăng) | D30: CO2, CH4 và N2O | E30: Thường xuyên | F30: x
A31: =+A30+1 -> 26 | B31: 3.2 | C31: Nhiên liệu sử dụng cho hoạt động cán bộ công nhân viên đi công tác bằng máy bay, tàu hỏa, tàu biển (DO, xăng, nhiên liệu phản lực) | D31: CO2, CH4 và N2O | E31: Thường xuyên | F31: x
A32: =+A31+1 -> 27 | B32: 3.3 | C32: Nhiên liệu sử dụng cho hoạt động vận chuyển nguyên vật liệu, hàng hoá từ nhà cung cấp đến Công ty (DO, xăng) | D32: CO2, CH4 và N2O | E32: Thường xuyên | F32: x
A33: =+A32+1 -> 28 | B33: 3.4 | C33: Nhiên liệu sử dụng cho hoạt động vận chuyển nguyên vật liệu, hàng hoá từ Công ty đến khách hàng (DO, xăng) | D33: CO2, CH4 và N2O | E33: Thường xuyên | F33: x
A34: =+A33+1 -> 29 | B34: 3.5 | C34: Nhiên liệu sử dụng cho hoạt động vận chuyển chất thải của nhà thầu xử lý chất thải (DO) | D34: CO2, CH4 và N2O | E34: Thường xuyên | F34: x
A35: =+A34+1 -> 30 | B35: 3.6 | C35: Vận chuyển, đi lại của nhà thầu khác (DO, xăng, điện (xe điện nếu có)) | D35: CO2, CH4 và N2O | E35: Thường xuyên | F35: x
A36: =+A35+1 -> 31 | B36: 3.7 | C36: Đi làm bằng ô tô, xe máy, xe điện (đạp - máy điện) của công nhân viên (DO, xăng, điện (xe điện nếu có)) | D36: CO2, CH4 và N2O | E36: Thường xuyên | F36: x
A37: =+A36+1 -> 32 | B37: 3.8 | C37: Môi chất lạnh từ các phương tiện vận chuyển (Môi chất lạnh trong điều hòa của xe) | D37: CO2, CH4 và N2O | E37: Thường xuyên | F37: o
A38: IV | B38: Cat 4 | C38: Phát thải gián tiếp từ việc tổ chức sử dụng các sản phẩm, dịch vụ.
A39: IV.1 | B39: 4.1 | C39: Thép
A40: 33 | B40: 4.1.1 | C40: Kim loại và thép cơ bản (basic iron and steel) | D40: CO2e | E40: Thường xuyên | F40: o
...

Sheet QT01.BM01
C1: BẢNG TỔNG HỢP MÃ NGUỒN PHÁT THẢI VÀ LOẠI BỎ KHÍ NHÀ KÍNH NĂM: 2024 | F1: QT01/BM.01
A2: STT | B2: Mã nguồn phát thải, loại bỏ KNK | C2: Nguồn phát thải/ Loại bỏ KNK | D2: Khí nhà kính | E2: Tần suất xuất hiện | F2: Hạng mục kiểm kê theo NĐ06/NĐ-CP
A3: I | B3: Cat 1 | C3: Phát thải và loại bỏ KNK trực tiếp
B4: 1.1 | C4: Đốt tĩnh
A5: =+A4+1 -> 1 | B5: 1.1.1 | C5: DO máy phát điện | D5: CO2, CH4 và N2O | E5: Thường xuyên | F5: x
A6: =+A5+1 -> 2 | B6: 1.1.2 | C6: LPG sản xuất | D6: CO2, CH4 và N2O | E6: Thường xuyên | F6: x
A7: =+A6+1 -> 3 | B7: 1.1.3 | C7: LPG nhà bếp | D7: CO2, CH4 và N2O | E7: Thường xuyên | F7: x
A8: =+A7+1 -> 4 | B8: 1.1.4 | C8: Methanol | D8: CO2 | E8: Thường xuyên | F8: x
A9: =+A8+1 -> 5 | B9: 1.1.5 | C9: Xăng máy cắt cỏ | D9: CO2, CH4 và N2O | E9: Thường xuyên | F9: x
A10: =+A9+1 -> 6 | B10: 1.1.6 | C10: Dầu hỏa (Kerosene-Oil) | D10: CO2, CH4 và N2O | E10: Thường xuyên | F10: x
A11: =+A10+1 -> 7 | B11: 1.1.7 | C11: Nước thủy tinh (Silicate) | D11: CO2 | E11: Thường xuyên | F11: x
A12: =+A11+1 -> 8 | B12: 1.1.8 | C12: Sơn lõi khuôn (BR-750 và Koalid Paste 94I) | D12: CO2 | E12: Thường xuyên | F12: x
A13: =+A12+1 -> 9 | B13: 1.1.10 | C13: Cồn công nghiệp C2H5OH | D13: CO2 | E13: Thường xuyên | F13: x
A14: =+A13+1 -> 10 | B14: 1.1.11 | C14: CO2 sử dụng cho kết dính thao (core mold) | D14: CO2 | E14: Thường xuyên | F14: x
B15: 1.2 | C15: Đốt trong di động
A16: 11 | B16: 1.2.1 | C16: DO dùng cho xe nâng | D16: CO2, CH4, N2O | E16: Thường xuyên | F16: x
A17: 16 | B17: 1.2.2 | C17: Xăng | D17: CO2, CH4, N2O | E17: Thường xuyên | F17: x
A18: 12 | B18: 1.2.2 | C18: DO dùng cho xe tải và xe car chở CBCNV | D18: CO2, CH4, N2O | E18: Thường xuyên | F18: x
A19: 13 | B19: 1.2.3 | C19: Xăng dùng cho xe 7 chỗ | D19: CO2, CH4, N2O | E19: Thường xuyên | F19: x
B20: 1.3 | C20: Phát thải rò rỉ
A21: 14 | B21: 1.3.1 | C21: CO2 sử dụng cho bình cứu hỏa, diễn tập PCCC | D21: CO2 | E21: Thỉnh thoảng | F21: x
A22: 15 | B22: 1.3.2 | C22: Môi chất lạnh | D22: R22, R32, R410A, R407C,… | E22: Thường xuyên | F22: x
A23: 16 | B23: 1.3.3 | C23: Xử lý nước thải tập trung | D23: CO2, CH4, N2O | E23: Thường xuyên | F23: x
A24: 17 | B24: 1.3.4 | C24: Số lượng phân bón sử dụng cho cây | D24: CO2, CH4, N2O | E24: Thỉnh thoảng | F24: x
A25: 18 | B25: 1.4 | C25: Cây xanh (nguồn hấp thụ) | D25: CO2 | E25: Thường xuyên | F25: x
A26: II | B26: Cat 2 | C26: Phát thải gián tiếp từ năng lượng nhập khẩu
A27: 19 | B27: 2.1 | C27: Điện lưới mua về sử dụng tại DISOCO | D27: CO2e | E27: Thường xuyên | F27: x
A28: III | B28: Cat 3 | C28: Phát thải gián tiếp từ hoạt động vận tải
A29: 20 | B29: 3.1 | C29: Nhiên liệu sử dụng cho hoạt động thuê xe đưa đón cán bộ công nhân viên (DO, xăng) | D29: CO2, CH4 và N2O | E29: Thường xuyên | F29: o
A30: 21 | B30: 3.2 | C30: Nhiên liệu sử dụng cho hoạt động cán bộ công nhân viên đi công tác bằng máy bay, tàu hỏa, tàu biển (DO, xăng, nhiên liệu phản lực) | D30: CO2, CH4 và N2O | E30: Thường xuyên | F30: o
A31: 22 | B31: 3.3 | C31: Nhiên liệu sử dụng cho hoạt động vận chuyển nguyên vật liệu, hàng hoá từ nhà cung cấp đến Công ty (DO, xăng) | D31: CO2, CH4 và N2O | E31: Thường xuyên | F31: o
A32: 23 | B32: 3.4 | C32: Nhiên liệu sử dụng cho hoạt động vận chuyển nguyên vật liệu, hàng hoá từ Công ty đến khách hàng (DO, xăng) | D32: CO2, CH4 và N2O | E32: Thường xuyên | F32: o
A33: 24 | B33: 3.5 | C33: Nhiên liệu sử dụng cho hoạt động vận chuyển chất thải của nhà thầu xử lý chất thải (DO) | D33: CO2, CH4 và N2O | E33: Thường xuyên | F33: o
A34: 25 | B34: 3.6 | C34: Vận chuyển, đi lại của nhà thầu khác (DO, xăng, điện (xe điện nếu có)) | D34: CO2, CH4 và N2O | E34: Thường xuyên | F34: o
A35: 26 | B35: 3.7 | C35: Đi làm bằng ô tô, xe máy, xe điện (đạp - máy điện) của công nhân viên (DO, xăng, điện (xe điện nếu có)) | D35: CO2, CH4 và N2O | E35: Thường xuyên | F35: o
A36: 27 | B36: 3.8 | C36: Môi chất lạnh từ các phương tiện vận chuyển (Môi chất lạnh trong điều hòa của xe) | D36: CO2, CH4 và N2O | E36: Thường xuyên | F36: o
A37: IV | B37: Cat 4 | C37: Phát thải gián tiếp từ việc tổ chức sử dụng các sản phẩm, dịch vụ
A38: IV.1 | B38: 4.1 | C38: Thép
A39: 28 | B39: 4.1.1 | C39: Kim loại và thép cơ bản (basic iron and steel) | D39: CO2e | E39: Thường xuyên | F39: o
A40: 29 | B40: 4.1.2 | C40: Thép phế (scrap metal) | D40: CO2e | E40: Thường xuyên | F40: o
...

Sheet QT01.BM02..
C1: BẢNG CÔNG BỐ PHẠM VI KIỂM KÊ KHÍ NHÀ KÍNH CẤP CƠ SỞ NĂM: 2024 | D1: GHG/QT01/BM03
A3: I. RANH GIỚI TỔ CHỨC
A4: 1. Tên công ty: Công ty TNHH MTV Diesel Sông Công
A5: 2. Địa chỉ trụ sở chính: số 362, đường Cách mạng Tháng 10, phường Châu Sơn, thành phố Sông Công, tỉnh Thái Nguyên - Việt Nam
A6: 3. Địa chỉ chi nhánh:
A7: 70 Lý Chiêu Hoàng, phường 10, Quận 6, thành phố Hồ Chí Minh
A8: Phường Sở Dầu, quận Hồng Bàng, thành phố Hải Phòng
A9: 4. Người đại diện theo Pháp luật: Ông Nguyễn Đức Tuấn Chức vụ: Giám đốc
A10: 5. Giấy phép đăng ký kinh doanh: Mã số 4600100211
A11: 6. Lĩnh vực sản xuất: Đúc, rèn, gia công cơ khí, lắp ráp
A12: 7. Nguyên tắc quản lý: Quản lý KNK theo nguyên tắc kiểm soát vận hành
A13: II. RANH GIỚI BÁO CÁO
A14: Khoảng thời gian kiểm kê: từ 01/01/2023 đến 31/12/2024
A15: Các nguồn phát thải và loại bỏ KNK áp dụng tính toán định lượng
A16: STT | B16: Mã nguồn Phát thải, loại bỏ KNK | C16: Nguồn phát thải/ Loại bỏ KNK | D16: Quá trình/ khu vực
A17: I | B17: Cat 1 | C17: Phát thải và loại bỏ KNK trực tiếp
A18: 1 | B18: 1.1 | C18: Đốt tĩnh
A19: 2 | B19: 1.1.1 | C19: DO | D19: Máy phát điện
A20: 3 | B20: 1.1.2 | C20: LPG sản xuất | D20: Sử dụng cho sản xuất (đốt sấy khuôn, chảo rót, hàn…)
A21: 4 | B21: 1.1.3 | C21: LPG nhà bếp | D21: Sử dụng cho bếp gas
A22: 5 | B22: 1.1.4 | C22: Toluen | D22: Sử dụng cho quá trình sản xuất, hệ số quy đổi lít ra kg
A23: 6 | B23: 1.1.5 | C23: Methanol | D23: Sử dụng cho quá trình sản xuất, hệ số quy đổi lít ra kg
A24: 7 | B24: 1.1.6 | C24: Xăng | D24: Sử dụng cho cắt cỏ,…
A25: 8 | B25: 1.1.7 | C25: Dầu hỏa | D25: Sử dụng cho quá trình ram chi tiết, cần thống kê loại dầu, thời gian tôi các sản phẩm, nhiệt độ phôi đưa vào tôi, nhiệt độ phôi sau tôi, nhiệt độ dầu lúc tôi.
A26: 9 | B26: 1.1.8 | C26: Nước thủy tinh (Silicate) | D26: Sử dụng cho quá trình trộn hỗn hợp làm thao. Cần phân tích trong thao
A27: 10 | B27: 1.1.9 | C27: Sơn khuôn | D27: Sử dụng cho quá trình sơn khuôn (BR-750,…)
A28: 11 | B28: 1.1.10 | C28: Sơn khuôn - Sepanol | D28: Sử dụng cho quá trình sơn khuôn.
A29: 12 | B29: 1.1.11 | C29: Cồn công nghiệp C2H5OH | D29: Sử dụng cho quá trình pha sơn dùng để sơn thao.
A30: 13 | B30: 1.1.12 | C30: CO2 sử dụng cho kết dính thao | D30: Sử dụng cho quá trình kết dính thao.
A31: 14 | B31: 1.2 | C31: Đốt động off-road (Xe vận chuyển nội bộ trong Nhà máy - Không đăng ký biển kiểm soát)
A32: 15 | B32: 1.2.1 | C32: DO | D32: Sử dụng cho xe vận chuyển nội bộ trong nhà máy (cho xe nâng, ...)
A33: 16 | B33: 1.2.2 | C33: Xăng | D33: Sử dụng cho xe vận chuyển nội bộ trong nhà máy (cho xe ...)
A34: 17 | B34: 1.3 | C34: Đốt động on-road (Xe vận tải, vận chuyển ngoài đường - Có đăng ký biển kiểm soát) và phát thải phát tán khác
A35: 18 | B35: 1.3.1 | C35: DO | D35: Sử dụng cho xe vận tải của Công ty (xe tải chở hàng, xe bán tải,…)
A36: 19 | B36: 1.3.2 | C36: Xăng | D36: Sử dụng cho xe chuyên chở CBCNV của Công ty
A37: 20 | B37: 1.4 | C37: CO2 sử dụng cho bình cứu hỏa, diễn tập PCCC | D37: Sử dụng cho bình cứu hỏa, diễn tập PCCC
A38: 21 | B38: 1.5 | C38: Môi chất lạnh | D38: Sử dụng môi chất lạnh cho các điều hòa, cấy nước nóng lạnh, tủ đông/ tủ cấp đá, chiller, máy sấy khí,…
A39: 22 | B39: 1.6 | C39: Xử lý nước thải tập trung | D39: Phát thải từ xử lý nước thải công nghiệp, có quan trắc chỉ số Nito tổng và COD ở đầu vào và đầu ra của quá trình (hiếu khí, thiếu khí, kỵ khí)
A40: 23 | B40: 1.7 | C40: Cây xanh (nguồn hấp thụ) | D40: Thống kê số lượng cây xanh, loại cây, tuổi cây và đường kính thân cây D1.3
A41: 24 | B41: 1.8 | C41: Số lượng phân bón sử dụng cho cây | D41: Thống kê số lượng cây xanh, loại cây, tuổi cây và đường kính thân cây D1.3
...

Sheet QT03.BM01
C1: BẢNG XÁC ĐỊNH MỨC ĐỘ Ý NGHĨA CÁC NGUỒN PHÁT THẢI GIÁN TIẾP KNK NĂM: 2024 | L1: QT03/BM.01
A2: Thông tin | C2: Thuộc yêu cầu của Các cơ quản quản lý nhà nước (R1) | D2: Thuộc yêu cầu của Khách hàng hoặc bên liên quan khác (R2) | E2: Liên quan đến mục tiêu khí nhà kính (R3) | F2: Dữ liệu cụ thể cho địa điểm/quá trình (R4) | G2: Chi phí để xác định lượng phát thải/loại bỏ KNK từ nguồn (R5) | H2: Khả năng để thu thập dữ liệu (R6) | I2: Hệ số phát thải/ mô hình định lượng (R7) | J2: Rủi ro và cơ hội khi thực hiện quản lý khí nhà kính (R8) | K2: Lượng phát thải hoặc loại bỏ gián tiếp được giả định về mặt định lương Độ lớn (ước tính) của lượng phát thải KNK (R9) 5% | L2: Điểm đánh giá | M2: Kết luận
A3: Trọng số tác động đến mô hình GHG | C3: 0.2 | D3: 0.15 | E3: 0.1 | F3: 0.05 | G3: 0.1 | H3: 0.1 | I3: 0.15 | J3: 0.1 | K3: 0.05
A4: Các tiêu chí đánh giá | C4: Có và bắt buộc áp dụng/ Yes: 3 | D4: Có và bắt buộc áp dụng/ Yes: 3 | E4: Có và bắt buộc áp dụng/ Yes: 3 | F4: Có định lượng rõ cho từng quá trình: 3 | G4: Chi phí cao ≥ 50 triệu: 1 | H4: Dễ/ Easy: 3 | I4: Có sẵn, phù hợp/ Available, suitable: 3 | J4: Có cơ hội mở rộng thị trường, khách hàng, sản phẩm (tăng trưởng kinh tế): 3 | K4: R10 ≥ 10%, 3
C5: Có nhưng không bắt buộc áp dụng/ 2 | D5: Có nhưng không bắt buộc áp dụng/ 2 | E5: Có nhưng không bắt buộc áp dụng/ 2 | F5: Có định lượng nhưng cho tổng thể địa điểm/ tổng quá trình: 2 | G5: Chi phí trung bình 10 triệu - 50 triệu: 2 | H5: Trung bình/ Medium: 2 | I5: Có sẵn, không phù hợp phải điều chỉnh/ Available, not suitable must be adjusted: 2 | J5: Có cơ hội nhận hỗ trợ về đầu tư công nghệ, máy móc, thiết bị, nâng cao (tăng trưởng công nghệ - kỹ thuật): 2 | K5: 2% ≤ R10 <10%: 2
C6: Không/ No: 1 | D6: Không/ No: 1 | E6: Không/ No: 1 | F6: Không có dữ liệu cụ thể: 1 | G6: Chi phí thấp < 10 triệu: 3 | H6: Khó/ Difficult: 1 | I6: Không có sẵn/ Not available: 1 | J6: Có rủi ro liên quan đến hình ảnh và thương hiệu của Công ty: 1 | K6: R10 < 2%: 1
A7: Mã nguồn phát thải và loại bỏ KNK | B7: Nguồn phát thải và loại bỏ KNK
A8: Cat 3 | B8: Phát thải gián tiếp từ hoạt động vận tải
A9: 3.1 | B9: Nhiên liệu sử dụng DO, xăng | C9: 1 | D9: 1 | E9: 1 | F9: 1 | G9: 3 | H9: 1 | I9: 2 | J9: 2 | K9: 1 | L9: =+SUMPRODUCT($C$3:$K$3,C9:K9) -> 1.45 | M9: =+IF(L9>=1.6,"YES","NO") -> NO
A10: 3.2 | B10: Nhiên liệu sử dụng DO, xăng, nhiên liệu phản lực | C10: 1 | D10: 1 | E10: 1 | F10: 1 | G10: 3 | H10: 1 | I10: 2 | J10: 2 | K10: 1 | L10: =+SUMPRODUCT($C$3:$K$3,C10:K10) -> 1.45 | M10: =+IF(L10>=1.6,"YES","NO") -> NO
A11: 3.3 | B11: Nhiên liệu sử dụng DO, xăng | C11: 1 | D11: 1 | E11: 1 | F11: 1 | G11: 3 | H11: 1 | I11: 2 | J11: 2 | K11: 1 | L11: =+SUMPRODUCT($C$3:$K$3,C11:K11) -> 1.45 | M11: =+IF(L11>=1.6,"YES","NO") -> NO
A12: 3.4 | B12: Nhiên liệu sử dụng DO, xăng | C12: 1 | D12: 1 | E12: 1 | F12: 1 | G12: 3 | H12: 1 | I12: 2 | J12: 2 | K12: 1 | L12: =+SUMPRODUCT($C$3:$K$3,C12:K12) -> 1.45 | M12: =+IF(L12>=1.6,"YES","NO") -> NO
A13: 3.5 | B13: Nhiên liệu sử dụng DO | C13: 1 | D13: 1 | E13: 1 | F13: 1 | G13: 3 | H13: 1 | I13: 2 | J13: 2 | K13: 1 | L13: =+SUMPRODUCT($C$3:$K$3,C13:K13) -> 1.45 | M13: =+IF(L13>=1.6,"YES","NO") -> NO
A14: 3.6 | B14: Nhiên liệu sử dụng DO, xăng, điện (xe điện nếu có) | C14: 1 | D14: 1 | E14: 1 | F14: 1 | G14: 3 | H14: 1 | I14: 2 | J14: 2 | K14: 1 | L14: =+SUMPRODUCT($C$3:$K$3,C14:K14) -> 1.45 | M14: =+IF(L14>=1.6,"YES","NO") -> NO
A15: 3.7 | B15: Nhiên liệu sử dụng DO, xăng, điện (xe điện nếu có) | C15: 1 | D15: 1 | E15: 1 | F15: 1 | G15: 3 | H15: 1 | I15: 2 | J15: 2 | K15: 1 | L15: =+SUMPRODUCT($C$3:$K$3,C15:K15) -> 1.45 | M15: =+IF(L15>=1.6,"YES","NO") -> NO
A16: 3.8 | B16: Môi chất lạnh từ các phương tiện vận chuyển | C16: 1 | D16: 1 | E16: 1 | F16: 1 | G16: 3 | H16: 1 | I16: 2 | J16: 2 | K16: 1 | L16: =+SUMPRODUCT($C$3:$K$3,C16:K16) -> 1.45 | M16: =+IF(L16>=1.6,"YES","NO") -> NO
A17: Cat 4 | B17: Phát thải gián tiếp từ việc tổ chức sử dụng các sản phẩm, dịch vụ.
A18: 4.1 | B18: Thép
A19: 4.1.1 | B19: Kim loại và thép cơ bản (basic iron and steel) | C19: 1 | D19: 2 | E19: 1 | F19: 1 | G19: 2 | H19: 1 | I19: 2 | J19: 2 | K19: 1 | L19: =+SUMPRODUCT($C$3:$K$3,C19:K19) -> 1.5 | M19: =+IF(L19>=1.6,"YES","NO") -> NO
A20: 4.1.2 | B20: Thép phế (scrap metal) | C20: 1 | D20: 2 | E20: 1 | F20: 1 | G20: 2 | H20: 1 | I20: 2 | J20: 2 | K20: 1 | L20: =+SUMPRODUCT($C$3:$K$3,C20:K20) -> 1.5 | M20: =+IF(L20>=1.6,"YES","NO") -> NO
A21: 4.2 | B21: Cát
A22: 4.2.1 | B22: Cát Silica | C22: 1 | D22: 1 | E22: 1 | F22: 1 | G22: 3 | H22: 1 | I22: 2 | J22: 2 | K22: 1 | L22: =+SUMPRODUCT($C$3:$K$3,C22:K22) -> 1.45 | M22: =+IF(L22>=1.6,"YES","NO") -> NO
A23: 4.2.2 | B23: Cát nhựa | C23: 1 | D23: 1 | E23: 1 | F23: 1 | G23: 3 | H23: 1 | I23: 2 | J23: 2 | K23: 1 | L23: =+SUMPRODUCT($C$3:$K$3,C23:K23) -> 1.45 | M23: =+IF(L23>=1.6,"YES","NO") -> NO
A24: 4.3 | B24: Phụ gia/ vật tư phụ khác cho đúc
A25: 4.3.1 | B25: Chất kết dính | C25: 1 | D25: 1 | E25: 1 | F25: 1 | G25: 3 | H25: 1 | I25: 2 | J25: 2 | K25: 1 | L25: =+SUMPRODUCT($C$3:$K$3,C25:K25) -> 1.45 | M25: =+IF(L25>=1.6,"YES","NO") -> NO
A26: 4.3.2 | B26: Chất làm cứng | C26: 1 | D26: 1 | E26: 1 | F26: 1 | G26: 3 | H26: 1 | I26: 2 | J26: 2 | K26: 1 | L26: =+SUMPRODUCT($C$3:$K$3,C26:K26) -> 1.45 | M26: =+IF(L26>=1.6,"YES","NO") -> NO
A27: 4.3.3 | B27: Chất hỗ trợ tạo bọt | C27: 1 | D27: 1 | E27: 1 | F27: 1 | G27: 3 | H27: 1 | I27: 2 | J27: 2 | K27: 1 | L27: =+SUMPRODUCT($C$3:$K$3,C27:K27) -> 1.45 | M27: =+IF(L27>=1.6,"YES","NO") -> NO
A28: 4.3.4 | B28: Chất chống xỉ | C28: 1 | D28: 1 | E28: 1 | F28: 1 | G28: 3 | H28: 1 | I28: 2 | J28: 2 | K28: 1 | L28: =+SUMPRODUCT($C$3:$K$3,C28:K28) -> 1.45 | M28: =+IF(L28>=1.6,"YES","NO") -> NO
A29: 4.3.5 | B29: Chất tăng độ bền nhiệt | C29: 1 | D29: 1 | E29: 1 | F29: 1 | G29: 3 | H29: 1 | I29: 2 | J29: 2 | K29: 1 | L29: =+SUMPRODUCT($C$3:$K$3,C29:K29) -> 1.45 | M29: =+IF(L29>=1.6,"YES","NO") -> NO
A30: 4.3.6 | B30: Chất làm lỏng | C30: 1 | D30: 1 | E30: 1 | F30: 1 | G30: 3 | H30: 1 | I30: 2 | J30: 2 | K30: 1 | L30: =+SUMPRODUCT($C$3:$K$3,C30:K30) -> 1.45 | M30: =+IF(L30>=1.6,"YES","NO") -> NO
A31: 4.3.7 | B31: Chất làm mịn bề mặt | C31: 1 | D31: 1 | E31: 1 | F31: 1 | G31: 3 | H31: 1 | I31: 2 | J31: 2 | K31: 1 | L31: =+SUMPRODUCT($C$3:$K$3,C31:K31) -> 1.45 | M31: =+IF(L31>=1.6,"YES","NO") -> NO
A32: 4.3.8 | B32: Chất khử oxy | C32: 1 | D32: 1 | E32: 1 | F32: 1 | G32: 3 | H32: 1 | I32: 2 | J32: 2 | K32: 1 | L32: =+SUMPRODUCT($C$3:$K$3,C32:K32) -> 1.45 | M32: =+IF(L32>=1.6,"YES","NO") -> NO
A33: 4.4 | B33: Hóa chất
A34: 4.4.1 | B34: RP7 | C34: 1 | D34: 1 | E34: 1 | F34: 1 | G34: 3 | H34: 1 | I34: 2 | J34: 2 | K34: 1 | L34: =+SUMPRODUCT($C$3:$K$3,C34:K34) -> 1.45 | M34: =+IF(L34>=1.6,"YES","NO") -> NO
A35: 4.4.2 | B35: Rỉ mật | C35: 1 | D35: 1 | E35: 1 | F35: 1 | G35: 3 | H35: 1 | I35: 2 | J35: 2 | K35: 1 | L35: =+SUMPRODUCT($C$3:$K$3,C35:K35) -> 1.45 | M35: =+IF(L35>=1.6,"YES","NO") -> NO
A36: 4.4.3 | B36: Javen | C36: 1 | D36: 1 | E36: 1 | F36: 1 | G36: 3 | H36: 1 | I36: 2 | J36: 2 | K36: 1 | L36: =+SUMPRODUCT($C$3:$K$3,C36:K36) -> 1.45 | M36: =+IF(L36>=1.6,"YES","NO") -> NO
A37: … | B37: …
A38: 4.5 | B38: Vật tư điện - điện tử | C38: 1 | D38: 1 | E38: 1 | F38: 1 | G38: 3 | H38: 1 | I38: 2 | J38: 2 | K38: 1 | L38: =+SUMPRODUCT($C$3:$K$3,C38:K38) -> 1.45 | M38: =+IF(L38>=1.6,"YES","NO") -> NO
A39: 4.5.1 | B39: …
A40: 4.5.2 | B40: …
...

Sheet QT01.BM02
C1: BẢNG CÔNG BỐ PHẠM VI KIỂM KÊ KHÍ NHÀ KÍNH CẤP CƠ SỞ NĂM: 2024 | D1: QT01/BM.03
A3: I. RANH GIỚI TỔ CHỨC
A4: 1. Tên công ty: Công ty TNHH
A5: 2. Địa chỉ trụ sở chính:
A6: 3. Địa chỉ chi nhánh:
A9: 4. Người đại diện theo Pháp luật: Ông Chức vụ: Giám đốc
A10: 5. Giấy phép đăng ký kinh doanh: Mã số
A11: 6. Lĩnh vực sản xuất: Đúc, rèn, gia công cơ khí, lắp ráp
A12: 7. Nguyên tắc quản lý: Quản lý KNK theo nguyên tắc kiểm soát vận hành
A13: II. RANH GIỚI BÁO CÁO
A14: Khoảng thời gian kiểm kê: từ 01/01/2024 đến 31/12/2024
A15: Các nguồn phát thải và loại bỏ KNK áp dụng tính toán định lượng
A16: STT | B16: Mã nguồn Phát thải, loại bỏ KNK | C16: Nguồn phát thải/ Loại bỏ KNK | D16: Quá trình/ khu vực
A17: I | B17: Cat 1 | C17: Phát thải và loại bỏ KNK trực tiếp
B18: 1.1 | C18: Đốt tĩnh
A19: 1 | B19: 1.1.1 | C19: DO máy phát điện | D19: Dùng cho máy phát điện
A20: 2 | B20: 1.1.2 | C20: LPG sản xuất | D20: Sử dụng cho sản xuất (đốt sấy khuôn, chảo rót, hàn…)
A21: 3 | B21: 1.1.3 | C21: LPG nhà bếp | D21: Sử dụng cho bếp gas
A22: 4 | B22: 1.1.4 | C22: Methanol | D22: Sử dụng cho quá trình sản xuất, hệ số quy đổi lít ra kg
A23: 5 | B23: 1.1.5 | C23: Xăng máy cắt cỏ | D23: Sử dụng cho cắt cỏ,…
A24: 6 | B24: 1.1.6 | C24: Dầu hỏa (Kerosene-Oil) | D24: Sử dụng cho quá trình ram chi tiết, cần thống kê loại dầu, thời gian tôi các sản phẩm, nhiệt độ phôi đưa vào tôi, nhiệt độ phôi sau tôi, nhiệt độ dầu lúc tôi.
A25: 7 | B25: 1.1.7 | C25: Nước thủy tinh (Silicate) | D25: Sử dụng cho quá trình trộn hỗn hợp làm thao. Cần phân tích trong thao
A26: 8 | B26: 1.1.8 | C26: Sơn lõi khuôn (BR-750 và Koalid Paste 94I) | D26: Sử dụng cho quá trình sơn lõi khuôn
A27: 9 | B27: 1.1.9 | C27: Cồn công nghiệp C2H5OH | D27: Sử dụng cho quá trình pha sơn dùng để sơn thao.
A28: 10 | B28: 1.1.10 | C28: CO2 sử dụng cho kết dính thao (core mold) | D28: Sử dụng cho quá trình kết dính thao (core mold)
B29: 1.2 | C29: Đốt trong di động
A30: 11 | B30: 1.2.1 | C30: DO dùng cho xe nâng | D30: Sử dụng cho xe nâng vận chuyển
A31: 12 | B31: 1.2.2 | C31: DO dùng cho xe tải và xe car chở CBCNV | D31: Sử dụng cho xe vận chuyển
A32: 13 | B32: 1.2.3 | C32: Xăng dùng cho xe 7 chỗ | D32: Sử dụng cho xe chuyên chở CBCNV của Công ty
B33: 1.3 | C33: Phát thải rò rỉ
A34: 14 | B34: 1.3.1 | C34: CO2 sử dụng cho bình cứu hỏa, diễn tập PCCC | D34: Sử dụng cho bình cứu hỏa, diễn tập PCCC
A35: 15 | B35: 1.3.2 | C35: Môi chất lạnh | D35: Sử dụng môi chất lạnh cho các điều hòa, cấy nước nóng lạnh, tủ đông/ tủ cấp đá, chiller, máy sấy khí,…
A36: 16 | B36: 1.3.3 | C36: Xử lý nước thải tập trung | D36: Phát thải từ xử lý nước thải sinh hoạt, có quan trắc chỉ số Nito tổng và COD ở đầu vào và đầu ra của quá trình (hiếu khí, thiếu khí, kỵ khí)
A37: 17 | B37: 1.3.4 | C37: Số lượng phân bón sử dụng cho cây | D37: Thống kê lượng phân bón sử dụng cho cây
A38: 18 | B38: 1.4 | C38: Cây xanh (nguồn hấp thụ) | D38: Thống kê số lượng cây xanh, loại cây, tuổi cây và đường kính thân cây D1.3
A39: II | B39: Cat 2 | C39: Phát thải gián tiếp từ năng lượng nhập khẩu
A40: 19 | B40: 2.1 | C40: Điện lưới mua về sử dụng | D40: Các quá trình sử dụng điện năng
A41: III | B41: Cat 3 | C41: Phát thải gián tiếp từ hoạt động vận tải
A42: 25 | B42: 3.1 | C42: Nhiên liệu sử dụng DO, xăng | D42: Các hoạt động thuê xe đưa đón CBCNV
A43: =+A42+1 -> 26 | B43: 3.2 | C43: Nhiên liệu sử dụng DO, xăng, nhiên liệu phản lực | D43: Các hoạt động cán bộ công nhân viên đi công tác bằng máy bay, tàu hỏa, tàu biển (DO, xăng, nhiên liệu phản lực)
...

Sheet QT03BM02.Độ khôngđảmbảotổng..
B1: BẢNG TÍNH TOÁN ĐỘ KHÔNG ĐẢM BẢO CÁC NGUỒN PHÁT THẢI KHÍ NHÀ KÍNH NĂM: 2024 | I1: GHG/QT03.BM02
A4: Cấp chính xác theo Phương pháp thống kê số liệu (M) | F4: Cấp chính xác của hệ số phát thải (F)
A5: Cách thức Method | C5: Điểm Point | F5: Cách thức Method | J5: Điểm Point
A6: Đo liên tục thông qua các thiết bị đo lường phù hợp Continuous measurement through suitable measuring devices | C6: 1 | F6: Hệ số phát thải từ phép đo lường hoặc tính toán cân bằng vật chất Direct measurement / calculation is not based on emission factor | J6: 1
A7: Đo theo tần suất lấy mẫu quy định (Ví dụ: 1 lần/ tháng,…) Measured according to the specified sampling frequency (e.g., once a month, ...). | C7: 2 | F7: Hệ số phát thải từ dữ liệu được cung cấp từ nhà cung cấp bên ngoài cho công ty Emission factor from data provided by an external supplier to the company (published). | J7: 2
F8: Hệ số phát thải có điều chỉnh theo đặc thù của ngành được công bố. Emission factor by industry characteristics (published). | J8: 3
A9: Tự thống kê (qua hoá đơn, ghi chép) Statistically (through invoices, notes) | C9: 3 | F9: Hệ số phát thải có điều chỉnh theo đặc thù của Quốc gia The emission factor is adjusted according to the characteristics of the country | J9: 4
A10: Ước lượng/ Tính toán Estimates | C10: 4 | F10: Hệ số phát thải theo khu vực được công bố. Emission factor by region (published). | J10: 5
F11: Hệ số phát thải theo Quốc tế (IPCC) International emission factor (IPCC) | J11: 6
A13: Mã Nguồn Source Code | B13: Nguồn Source | C13: Phương pháp thống kê số liệu Statistical methods | D13: Điểm (M) Point (M) | E13: Loại hệ số phát thải Type of emission factor | F13: Điểm (F) Point | G13: Điểm cấp chính xác Point accuracy level Ui | H13: Lượng phát thải CO2e | I13: Tỷ lệ % GHG theo nguồn Ratio % GHG by source xi | J13: Quy đổi Convert Ui*xi | K13: Quy đổi Convert (10^-4)*(Ui*xi)^2
A14: Cat 1 | B14: Phát thải trực tiếp
A15: 1.1 | B15: Đốt tĩnh
A16: 1.1.1 | B16: DO Máy phát điện | C16: Tự thống kê (qua hoá đơn, ghi chép) | D16: 3 | E16: QĐ2626/BTNMT | F16: 4 | G16: =+SQRT(D16*F16) -> 3.4641016 | H16: =+'QT02BM01Bảng địnhluongLoaiKhí..'!$G$8 -> 0.95802776 | I16: =+H16/$H$39 -> #REF! | J16: =G16*I16 -> #REF! | K16: =+J16^2/10^-4 -> #REF!
A17: 1.1.2 | B17: LPG sản xuất | C17: Đo theo tần suất lấy mẫu quy định: 01 tháng/ lần | D17: 2 | E17: QĐ2626/BTNMT | F17: 4 | G17: =+SQRT(D17*F17) -> 2.8284271 | H17: =+'QT02BM01Bảng địnhluongLoaiKhí..'!$G$9 -> 83.522361 | I17: =+H17/$H$39 -> #REF! | J17: =G17*I17 -> #REF! | K17: =+J17^2/10^-4 -> #REF!
A18: 1.1.3 | B18: LPG nhà ăn | C18: Đo theo tần suất lấy mẫu quy định: 01 tháng/ lần | D18: 2 | E18: QĐ2626/BTNMT | F18: 4 | G18: =+SQRT(D18*F18) -> 2.8284271 | H18: =+'QT02BM01Bảng địnhluongLoaiKhí..'!$G$10 -> 6.248381 | I18: =+H18/$H$39 -> #REF! | J18: =G18*I18 -> #REF! | K18: =+J18^2/10^-4 -> #REF!
A19: 1.1.5 | B19: Methanol | C19: Đo theo tần suất lấy mẫu quy định: 01 tháng/ lần | D19: 2 | E19: IPCC 2006 | F19: 1 | G19: =+SQRT(D19*F19) -> 1.4142136 | H19: =+'QT02BM01Bảng địnhluongLoaiKhí..'!$G$11 -> 0.275 | I19: =+H19/$H$39 -> #REF! | J19: =G19*I19 -> #REF! | K19: =+J19^2/10^-4 -> #REF!
A20: 1.1.6 | B20: Xăng MCC, PCCC | C20: Tự thống kê (qua hoá đơn, ghi chép) | D20: 3 | E20: QĐ2626/BTNMT | F20: 3 | G20: =+SQRT(D20*F20) -> 3 | H20: =+'QT02BM01Bảng địnhluongLoaiKhí..'!$G$12 -> 0.34751889 | I20: =+H20/$H$39 -> #REF! | J20: =G20*I20 -> #REF! | K20: =+J20^2/10^-4 -> #REF!
A21: 1.1.7 | B21: Dầu hỏa | C21: Đo theo tần suất lấy mẫu quy định: 01 tháng/ lần | D21: 2 | E21: QĐ2626/BTNMT | F21: 4 | G21: =+SQRT(D21*F21) -> 2.8284271 | H21: =+'QT02BM01Bảng địnhluongLoaiKhí..'!$G$13 -> 512.57316 | I21: =+H21/$H$39 -> #REF! | J21: =G21*I21 -> #REF! | K21: =+J21^2/10^-4 -> #REF!
A22: 1.1.8 | B22: Nước thủy tinh (Silicate) | C22: Đo theo tần suất lấy mẫu quy định: 01 tháng/ lần | D22: 2 | E22: IPCC 2006 | F22: 1 | G22: =+SQRT(D22*F22) -> 1.4142136 | H22: =+'QT02BM01Bảng địnhluongLoaiKhí..'!$G$14 -> 1.094552 | I22: =+H22/$H$39 -> #REF! | J22: =G22*I22 -> #REF! | K22: =+J22^2/10^-4 -> #REF!
A23: 1.1.9 | B23: Sơn khuôn BR-750 +sơn thao LOALIDPASTE 94l | C23: Đo theo tần suất lấy mẫu quy định: 01 tháng/ lần | D23: 2 | E23: IPCC 2006 | F23: 1 | G23: =+SQRT(D23*F23) -> 1.4142136 | H23: =+'QT02BM01Bảng địnhluongLoaiKhí..'!$G$15 -> 9.9407865 | I23: =+H23/$H$39 -> #REF! | J23: =G23*I23 -> #REF! | K23: =+J23^2/10^-4 -> #REF!
A24: 1.1.10 | B24: Sơn khuôn - Sepanol | C24: Đo theo tần suất lấy mẫu quy định: 01 tháng/ lần | D24: 2 | E24: IPCC 2006 | F24: 1 | G24: =+SQRT(D24*F24) -> 1.4142136 | H24: =+'QT02BM01Bảng địnhluongLoaiKhí..'!$G$16 -> #REF! | I24: =+H24/$H$39 -> #REF! | J24: =G24*I24 -> #REF! | K24: =+J24^2/10^-4 -> #REF!
A25: 1.1.11 | B25: Cồn công nghiệp C2H5OH | C25: Đo theo tần suất lấy mẫu quy định: 01 tháng/ lần | D25: 2 | E25: IPCC 2006 | F25: 1 | G25: =+SQRT(D25*F25) -> 1.4142136 | H25: =+'QT02BM01Bảng địnhluongLoaiKhí..'!$G$17 -> 59.016019 | I25: =+H25/$H$39 -> #REF! | J25: =G25*I25 -> #REF! | K25: =+J25^2/10^-4 -> #REF!
A26: 1.1.11 | B26: CO2 cho làm thao | C26: Đo theo tần suất lấy mẫu quy định: 01 tháng/ lần | D26: 2 | E26: IPCC 2006 | F26: 1 | G26: =+SQRT(D26*F26) -> 1.4142136 | H26: =+'QT02BM01Bảng địnhluongLoaiKhí..'!$G$18 -> 118.25098 | I26: =+H26/$H$39 -> #REF! | J26: =G26*I26 -> #REF! | K26: =+J26^2/10^-4 -> #REF!
A27: 1.2 | B27: Đốt động off-road (Xe vận chuyển nội bộ trong Nhà máy - Không đăng ký biển kiểm soát)
A28: 1.2.1 | B28: DO xe nâng | C28: Đo theo tần suất lấy mẫu quy định: 01 tháng/ lần | D28: 2 | E28: QĐ2626/BTNMT | F28: 4 | G28: =+SQRT(D28*F28) -> 2.8284271 | H28: =+'QT02BM01Bảng địnhluongLoaiKhí..'!$G$20 -> 45.515836 | I28: =+H28/$H$39 -> #REF! | J28: =G28*I28 -> #REF! | K28: =+J28^2/10^-4 -> #REF!
A29: 1.2.2 | B29: Xăng | C29: Đo theo tần suất lấy mẫu quy định: 01 tháng/ lần | D29: 2 | E29: QĐ2626/BTNMT | F29: 4 | G29: =+SQRT(D29*F29) -> 2.8284271 | I29: =+H29/$H$39 -> #REF! | J29: =G29*I29 -> #REF! | K29: =+J29^2/10^-4 -> #REF!
A30: 1.3 | B30: Đốt động on-road (Xe vận tải, vận chuyển ngoài đường - Có đăng ký biển kiểm soát)
A31: 1.3.1 | B31: DO xe vận tải nội bộ + bên ngoài | C31: Đo theo tần suất lấy mẫu quy định: 01 tháng/ lần | D31: 2 | E31: QĐ2626/BTNMT | F31: 4 | G31: =+SQRT(D31*F31) -> 2.8284271 | H31: =+'QT02BM01Bảng địnhluongLoaiKhí..'!$G$23 -> #REF! | I31: =+H31/$H$39 -> #REF! | J31: =G31*I31 -> #REF! | K31: =+J31^2/10^-4 -> #REF!
A32: 1.3.2 | B32: Xăng xe vận tải bên ngoài | C32: Đo theo tần suất lấy mẫu quy định: 01 tháng/ lần | D32: 2 | E32: QĐ2626/BTNMT | F32: 4 | G32: =+SQRT(D32*F32) -> 2.8284271 | H32: =+'QT02BM01Bảng địnhluongLoaiKhí..'!$G$24 -> 11.86119 | I32: =+H32/$H$39 -> #REF! | J32: =G32*I32 -> #REF! | K32: =+J32^2/10^-4 -> #REF!
A33: 1.4 | B33: Bình chữa cháy CO2 | C33: Tự thống kê (qua hoá đơn, ghi chép) | D33: 3 | E33: TCVN 7026:2013 | F33: 3 | G33: =+SQRT(D33*F33) -> 3 | H33: =+'QT02BM01Bảng địnhluongLoaiKhí..'!$G$25 -> 0.0074 | I33: =+H33/$H$39 -> #REF! | J33: =G33*I33 -> #REF! | K33: =+J33^2/10^-4 -> #REF!
A34: 1.5 | B34: Môi chất lạnh | C34: Tự thống kê (qua hoá đơn, ghi chép) | D34: 3 | E34: IPCC 2006 & 2019 | F34: 4 | G34: =+SQRT(D34*F34) -> 3.4641016 | H34: =+'QT02BM01Bảng địnhluongLoaiKhí..'!$G$26 -> 12.59382 | I34: =+H34/$H$39 -> #REF! | J34: =G34*I34 -> #REF! | K34: =+J34^2/10^-4 -> #REF!
A35: 1.6 | B35: Xử lý nước thải tập trung | C35: Đo theo tần suất lấy mẫu quy định: 01 tháng/ lần | D35: 2 | E35: IPCC 2019 | F35: 4 | G35: =+SQRT(D35*F35) -> 2.8284271 | H35: =+'QT02BM01Bảng địnhluongLoaiKhí..'!$G$27 -> 26.604561 | I35: =+H35/$H$39 -> #REF! | J35: =G35*I35 -> #REF! | K35: =+J35^2/10^-4 -> #REF!
A36: 1.7 | B36: Số lượng phân bón sử dụng cho cây | C36: Tự thống kê (qua ghi chép) | D36: 3 | E36: IPCC 2019 | F36: 6 | G36: =+SQRT(D36*F36) -> 4.2426407 | H36: =+'QT02BM01Bảng địnhluongLoaiKhí..'!$G$28 -> 0.05577 | I36: =+H36/$H$39 -> #REF! | J36: =G36*I36 -> #REF! | K36: =+J36^2/10^-4 -> #REF!
A37: Cat 2 | B37: Phát thải gián tiếp từ năng lượng nhập khẩu
A38: 2.1 | B38: Điện năng mua từ lưới điện EVN sử dụng tại DISOCO | C38: Đo liên tục thông qua các thiết bị đo lường phù hợp | D38: 1 | E38: 1726/BĐKH-PTCBT | F38: 3 | G38: =+SQRT(D38*F38) -> 1.7320508 | H38: =+'QT02BM01Bảng địnhluongLoaiKhí..'!$G$30 -> 15779.5 | I38: =+H38/$H$39 -> #REF! | J38: =G38*I38 -> #REF! | K38: =+J38^2/10^-4 -> #REF!
A39: TỔNG CỘNG (tấn CO2e) | H39: =+SUM(H16:H38) -> #REF! | I39: =+SUM(I16:I38) -> #REF!
A40: Độ không đảm bảo tổng thể U_total | K40: =10^-2*SQRT(SUM(K16:K38)) -> #REF!
A41: Cấp chính xác của bảng số liệu The correct level of the data table | K41: =IF(K40>4,"Level E",IF(K40>3,"Level D",IF(K40>2,"Level C",IF(K40>1,"Level B","Level A")))) -> #REF!
E43: Cấp chính xác | F43: Điểm (x) | G43: Mức độ chính xác
E44: A | F44: x <=1 | G44: Rất tốt Very good
...

Sheet QT03BM02.Độ khôngđảmbảotổng
B1: BẢNG TÍNH TOÁN ĐỘ KHÔNG ĐẢM BẢO TỔNG THỂ CÁC NGUỒN PHÁT THẢI KHÍ NHÀ KÍNH NĂM: 2024 | I1: QT03/BM.02
A4: Cấp chính xác theo Phương pháp thống kê số liệu (M) | F4: Cấp chính xác của hệ số phát thải (F)
A5: Cách thức Method | C5: Điểm Point | F5: Cách thức Method | J5: Điểm Point
A6: Đo liên tục thông qua các thiết bị đo lường phù hợp Continuous measurement through suitable measuring devices | C6: 1 | F6: Hệ số phát thải từ phép đo lường hoặc tính toán cân bằng vật chất Direct measurement / calculation is not based on emission factor | J6: 1
A7: Đo theo tần suất lấy mẫu quy định (Ví dụ: 1 lần/ tháng,…) Measured according to the specified sampling frequency (e.g., once a month, ...). | C7: 2 | F7: Hệ số phát thải từ dữ liệu được cung cấp từ nhà cung cấp bên ngoài cho công ty Emission factor from data provided by an external supplier to the company (published). | J7: 2
F8: Hệ số phát thải có điều chỉnh theo đặc thù của ngành được công bố. Emission factor by industry characteristics (published). | J8: 3
A9: Tự thống kê (qua hoá đơn, ghi chép) Statistically (through invoices, notes) | C9: 3 | F9: Hệ số phát thải có điều chỉnh theo đặc thù của Quốc gia The emission factor is adjusted according to the characteristics of the country | J9: 4
A10: Ước lượng/ Tính toán Estimates | C10: 4 | F10: Hệ số phát thải theo khu vực được công bố. Emission factor by region (published). | J10: 5
F11: Hệ số phát thải theo Quốc tế (IPCC) International emission factor (IPCC) | J11: 6
A13: Mã Nguồn Source Code | B13: Nguồn Source | C13: Phương pháp thống kê số liệu Statistical methods | D13: Điểm (M) Point (M) | E13: Loại hệ số phát thải Type of emission factor | F13: Điểm (F) Point | G13: Điểm cấp chính xác Point accuracy level Ui | H13: Lượng phát thải CO2e | I13: Tỷ lệ % GHG theo nguồn Ratio % GHG by source xi | J13: Quy đổi Convert Ui*xi | K13: Quy đổi Convert (10^4)*(Ui*xi)^2 | M13: Do giá trị tính toán (Ui*xi)^2 nhỏ lên nhân với 10 mũ 4 (hay chính là chia cho 10 mũ -4) và kết quả sau khi khai căn nhân với 10 mũ (-2) để format số các chữ số sau dấu phẩy cho dễ nhìn tránh toàn số 0 sau dấu phẩy. Tự tiệt tiêu do nhân 10^4 trong căn với 10^-2 ngoài căn
A14: Cat 1 | B14: Phát thải trực tiếp
A15: 1.1 | B15: Đốt tĩnh
A16: 1.1.1 | B16: DO máy phát điện | C16: Tự thống kê (qua hoá đơn, ghi chép) | D16: 3 | E16: QĐ2626/BTNMT | F16: 4 | G16: =+SQRT(D16*F16) -> 3.4641016 | H16: =+'QT02BM01Bảng địnhluongLoaiKhí..'!$G$8 -> 0.95802776 | I16: =+H16/$H$38 -> 5.6668697e-05 | J16: =G16*I16 -> 0.00019630612 | K16: =+J16^2/10^-4 -> 0.00038536094
A17: 1.1.2 | B17: LPG sản xuất | C17: Đo theo tần suất lấy mẫu quy định: 01 tháng/ lần | D17: 2 | E17: QĐ2626/BTNMT | F17: 4 | G17: =+SQRT(D17*F17) -> 2.8284271 | H17: =+'QT02BM01Bảng địnhluongLoaiKhí..'!$G$9 -> 83.522361 | I17: =+H17/$H$38 -> 0.0049404658 | J17: =G17*I17 -> 0.013973747 | K17: =+J17^2/10^-4 -> 1.9526562
A18: 1.1.3 | B18: LPG nhà bếp | C18: Đo theo tần suất lấy mẫu quy định: 01 tháng/ lần | D18: 2 | E18: QĐ2626/BTNMT | F18: 4 | G18: =+SQRT(D18*F18) -> 2.8284271 | H18: =+'QT02BM01Bảng địnhluongLoaiKhí..'!$G$10 -> 6.248381 | I18: =+H18/$H$38 -> 0.00036960057 | J18: =G18*I18 -> 0.0010453883 | K18: =+J18^2/10^-4 -> 0.010928367
A19: 1.1.4 | B19: Methanol | C19: Đo theo tần suất lấy mẫu quy định: 01 tháng/ lần | D19: 2 | E19: IPCC 2006 | F19: 1 | G19: =+SQRT(D19*F19) -> 1.4142136 | H19: =+'QT02BM01Bảng địnhluongLoaiKhí..'!$G$11 -> 0.275 | I19: =+H19/$H$38 -> 1.6266639e-05 | J19: =G19*I19 -> 2.3004501e-05 | K19: =+J19^2/10^-4 -> 5.2920708e-06
A20: 1.1.5 | B20: Xăng máy cắt cỏ | C20: Tự thống kê (qua hoá đơn, ghi chép) | D20: 3 | E20: QĐ2626/BTNMT | F20: 3 | G20: =+SQRT(D20*F20) -> 3 | H20: =+'QT02BM01Bảng địnhluongLoaiKhí..'!$G$12 -> 0.34751889 | I20: =+H20/$H$38 -> 2.0556234e-05 | J20: =G20*I20 -> 6.1668701e-05 | K20: =+J20^2/10^-4 -> 3.8030287e-05
A21: 1.1.6 | B21: Dầu hỏa (Kerosene-Oil) | C21: Đo theo tần suất lấy mẫu quy định: 01 tháng/ lần | D21: 2 | E21: QĐ2626/BTNMT | F21: 4 | G21: =+SQRT(D21*F21) -> 2.8284271 | H21: =+'QT02BM01Bảng địnhluongLoaiKhí..'!$G$13 -> 512.57316 | I21: =+H21/$H$38 -> 0.030319427 | J21: =G21*I21 -> 0.08575629 | K21: =+J21^2/10^-4 -> 73.541413
A22: 1.1.7 | B22: Nước thủy tinh (Silicate) | C22: Đo theo tần suất lấy mẫu quy định: 01 tháng/ lần | D22: 2 | E22: IPCC 2006 | F22: 1 | G22: =+SQRT(D22*F22) -> 1.4142136 | H22: =+'QT02BM01Bảng địnhluongLoaiKhí..'!$G$14 -> 1.094552 | I22: =+H22/$H$38 -> 6.4744299e-05 | J22: =G22*I22 -> 9.1562265e-05 | K22: =+J22^2/10^-4 -> 8.3836485e-05
A23: 1.1.8 | B23: Sơn lõi khuôn (BR-750 và Koalid Paste 94I) | C23: Đo theo tần suất lấy mẫu quy định: 01 tháng/ lần | D23: 2 | E23: IPCC 2006 | F23: 1 | G23: =+SQRT(D23*F23) -> 1.4142136 | H23: =+'QT02BM01Bảng địnhluongLoaiKhí..'!$G$15 -> 9.9407865 | I23: =+H23/$H$38 -> 0.00058801158 | J23: =G23*I23 -> 0.00083157395 | K23: =+J23^2/10^-4 -> 0.0069151524
A24: 1.1.9 | B24: Cồn công nghiệp C2H5OH | C24: Đo theo tần suất lấy mẫu quy định: 01 tháng/ lần | D24: 2 | E24: IPCC 2006 | F24: 1 | G24: =+SQRT(D24*F24) -> 1.4142136 | H24: =+'QT02BM01Bảng địnhluongLoaiKhí..'!$G$17 -> 59.016019 | I24: =+H24/$H$38 -> 0.003490881 | J24: =G24*I24 -> 0.0049368513 | K24: =+J24^2/10^-4 -> 0.243725
A25: 1.1.10 | B25: CO2 sử dụng cho kết dính thao (core mold) | C25: Đo theo tần suất lấy mẫu quy định: 01 tháng/ lần | D25: 2 | E25: IPCC 2006 | F25: 1 | G25: =+SQRT(D25*F25) -> 1.4142136 | H25: =+'QT02BM01Bảng địnhluongLoaiKhí..'!$G$18 -> 118.25098 | I25: =+H25/$H$38 -> 0.0069947129 | J25: =G25*I25 -> 0.0098920178 | K25: =+J25^2/10^-4 -> 0.97852017
A26: 1.2 | B26: Đốt trong di động
A27: 1.2.1 | B27: DO dùng cho xe nâng | C27: Đo theo tần suất lấy mẫu quy định: 01 tháng/ lần | D27: 2 | E27: QĐ2626/BTNMT | F27: 4 | G27: =+SQRT(D27*F27) -> 2.8284271 | H27: =+'QT02BM01Bảng địnhluongLoaiKhí..'!$G$20 -> 45.515836 | I27: =+H27/$H$38 -> 0.002692326 | J27: =G27*I27 -> 0.007615048 | K27: =+J27^2/10^-4 -> 0.57988956
A28: 1.2.2 | B28: Xăng | C28: Đo theo tần suất lấy mẫu quy định: 01 tháng/ lần | D28: 2 | E28: QĐ2626/BTNMT | F28: 4 | G28: =+SQRT(D28*F28) -> 2.8284271 | I28: =+H28/$H$38 -> 0 | J28: =G28*I28 -> 0 | K28: =+J28^2/10^-4 -> 0
A29: 1.2.2 | B29: DO dùng cho xe tải và xe car chở CBCNV | C29: Đo theo tần suất lấy mẫu quy định: 01 tháng/ lần | D29: 2 | E29: QĐ2626/BTNMT | F29: 4 | G29: =+SQRT(D29*F29) -> 2.8284271 | H29: =+'QT02BM01Bảng địnhluong Loai'!G20 -> 237.40165 | I29: =+H29/$H$38 -> 0.014042644 | J29: =G29*I29 -> 0.039718594 | K29: =+J29^2/10^-4 -> 15.775667
A30: 1.2.3 | B30: Xăng dùng cho xe 7 chỗ | C30: Đo theo tần suất lấy mẫu quy định: 01 tháng/ lần | D30: 2 | E30: QĐ2626/BTNMT | F30: 4 | G30: =+SQRT(D30*F30) -> 2.8284271 | H30: =+'QT02BM01Bảng địnhluongLoaiKhí..'!$G$24 -> 11.86119 | I30: =+H30/$H$38 -> 0.00070160619 | J30: =G30*I30 -> 0.001984442 | K30: =+J30^2/10^-4 -> 0.0393801
A31: 1.3 | B31: Phát thải rò rỉ
A32: 1.3.1 | B32: CO2 sử dụng cho bình cứu hỏa, diễn tập PCCC | C32: Tự thống kê (qua hoá đơn, ghi chép) | D32: 3 | E32: TCVN 7026:2013 | F32: 3 | G32: =+SQRT(D32*F32) -> 3 | H32: =+'QT02BM01Bảng địnhluongLoaiKhí..'!$G$25 -> 0.0074 | I32: =+H32/$H$38 -> 4.3772047e-07 | J32: =G32*I32 -> 1.3131614e-06 | K32: =+J32^2/10^-4 -> 1.7243929e-08
A33: 1.3.2 | B33: Môi chất lạnh | C33: Tự thống kê (qua hoá đơn, ghi chép) | D33: 3 | E33: IPCC 2006 & 2019 | F33: 4 | G33: =+SQRT(D33*F33) -> 3.4641016 | H33: =+'QT02BM01Bảng địnhluongLoaiKhí..'!$G$26 -> 12.59382 | I33: =+H33/$H$38 -> 0.00074494226 | J33: =G33*I33 -> 0.0025805557 | K33: =+J33^2/10^-4 -> 0.066592677
A34: 1.3.3 | B34: Xử lý nước thải tập trung | C34: Đo theo tần suất lấy mẫu quy định: 01 tháng/ lần | D34: 2 | E34: IPCC 2019 | F34: 4 | G34: =+SQRT(D34*F34) -> 2.8284271 | H34: =+'QT02BM01Bảng địnhluongLoaiKhí..'!$G$27 -> 26.604561 | I34: =+H34/$H$38 -> 0.0015736974 | J34: =G34*I34 -> 0.0044510884 | K34: =+J34^2/10^-4 -> 0.19812188
A35: 1.3.4 | B35: Số lượng phân bón sử dụng cho cây | C35: Tự thống kê (qua ghi chép) | D35: 3 | E35: IPCC 2019 | F35: 6 | G35: =+SQRT(D35*F35) -> 4.2426407 | H35: =+'QT02BM01Bảng địnhluongLoaiKhí..'!$G$28 -> 0.05577 | I35: =+H35/$H$38 -> 3.2988744e-06 | J35: =G35*I35 -> 1.3995939e-05 | K35: =+J35^2/10^-4 -> 1.958863e-06
A36: Cat 2 | B36: Phát thải gián tiếp từ năng lượng nhập khẩu
A37: 2.1 | B37: Điện năng mua từ lưới điện EVN sử dụng | C37: Đo liên tục thông qua các thiết bị đo lường phù hợp | D37: 1 | E37: 1726/BĐKH-PTCBT | F37: 3 | G37: =+SQRT(D37*F37) -> 1.7320508 | H37: =+'QT02BM01Bảng địnhluongLoaiKhí..'!$G$30 -> 15779.5 | I37: =+H37/$H$38 -> 0.93337971 | J37: =G37*I37 -> 1.6166611 | K37: =+J37^2/10^-4 -> 26135.931
A38: TỔNG CỘNG (tấn CO2e) | H38: =+SUM(H16:H37) -> 16905.767 | I38: =+SUM(I16:I37) -> 1
A39: Độ không đảm bảo tổng thể U_total | K39: =10^-2*SQRT(SUM(K16:K37)) -> 1.619547
A40: Cấp chính xác của bảng số liệu The correct level of the data table | K40: =IF(K39>4,"Level E",IF(K39>3,"Level D",IF(K39>2,"Level C",IF(K39>1,"Level B","Level A")))) -> Level B
E42: Cấp chính xác | F42: Điểm (x) | G42: Mức độ chính xác
E43: A | F43: x <=1 | G43: Rất tốt Very good
E44: B | F44: 1<x<=2 | G44: Tốt Good
...

Sheet QT03BM02.Độ khôngđảmbảo Cat12..
B1: BẢNG TÍNH TOÁN ĐỘ KHÔNG ĐẢM BẢO CÁC NGUỒN PHÁT THẢI KHÍ NHÀ KÍNH NĂM: 2024 | I1: GHG/QT03.BM02
A3: Cấp chính xác theo Phương pháp thống kê số liệu (M) | F3: Cấp chính xác của hệ số phát thải (F)
A4: Cách thức Method | C4: Điểm Point | F4: Cách thức Method | J4: Điểm Point
A5: Đo liên tục thông qua các thiết bị đo lường phù hợp Continuous measurement through suitable measuring devices | C5: 1 | F5: Hệ số phát thải từ phép đo lường hoặc tính toán cân bằng vật chất Direct measurement / calculation is not based on emission factor | J5: 1
A6: Đo theo tần suất lấy mẫu quy định (Ví dụ: 1 lần/ tháng,…) Measured according to the specified sampling frequency (e.g., once a month, ...). | C6: 2 | F6: Hệ số phát thải từ dữ liệu được cung cấp từ nhà cung cấp bên ngoài cho công ty Emission factor from data provided by an external supplier to the company (published). | J6: 2
F7: Hệ số phát thải có điều chỉnh theo đặc thù của ngành được công bố. Emission factor by industry characteristics (published). | J7: 3
A8: Tự thống kê (qua hoá đơn, ghi chép) Statistically (through invoices, notes) | C8: 3 | F8: Hệ số phát thải có điều chỉnh theo đặc thù của Quốc gia The emission factor is adjusted according to the characteristics of the country | J8: 4
A9: Ước lượng/ Tính toán Estimates | C9: 4 | F9: Hệ số phát thải theo khu vực được công bố. Emission factor by region (published). | J9: 5
F10: Hệ số phát thải theo Quốc tế (IPCC) International emission factor (IPCC) | J10: 6
A12: Mã Nguồn Source Code | B12: Nguồn Source | C12: Phương pháp thống kê số liệu Statistical methods | D12: Điểm (M) Point (M) | E12: Loại hệ số phát thải Type of emission factor | F12: Điểm (F) Point | G12: Điểm cấp chính xác Point accuracy level Ui | H12: Lượng phát thải CO2e | I12: Tỷ lệ % GHG theo nguồn Ratio % GHG by source xi | J12: Quy đổi Convert Ui*xi | K12: Quy đổi Convert (10^-4)*(Ui*xi)^2
A13: Cat 1 | B13: Phát thải trực tiếp
A14: Độ không đảm bảo Cat 1 U_total_Cat 1 | K14: =10^-2*SQRT(SUM(K18:K38)) -> #REF!
A15: Cấp chính xác của bảng số liệu The correct level of the data table | K15: =IF(K14>4,"Level E",IF(K14>3,"Level D",IF(K14>2,"Level C",IF(K14>1,"Level B","Level A")))) -> #REF!
A16: TỔNG CỘNG (tấn CO2e) | H16: =+SUM(H18:H38) -> #REF! | I16: =+SUM(I18:I38) -> #REF!
A17: 1.1 | B17: Đốt tĩnh
A18: 1.1.1 | B18: DO Máy phát điện | C18: Tự thống kê (qua hoá đơn, ghi chép) | D18: 3 | E18: QĐ2626/BTNMT | F18: 4 | G18: =+SQRT(D18*F18) -> 3.4641016 | H18: =+'1.1.1 DO Máy phát điện'!$N$25 -> 0.95802776 | I18: =+H18/$H$16 -> #REF! | J18: =G18*I18 -> #REF! | K18: =+J18^2/10^-4 -> #REF!
A19: 1.1.2 | B19: LPG sản xuất | C19: Đo theo tần suất lấy mẫu quy định: 01 tháng/ lần | D19: 2 | E19: QĐ2626/BTNMT | F19: 4 | G19: =+SQRT(D19*F19) -> 2.8284271 | H19: =+'1.1.2 Gas LPG SX'!$N$25 -> 83.522361 | I19: =+H19/$H$16 -> #REF! | J19: =G19*I19 -> #REF! | K19: =+J19^2/10^-4 -> #REF!
A20: 1.1.3 | B20: LPG nhà ăn | C20: Đo theo tần suất lấy mẫu quy định: 01 tháng/ lần | D20: 2 | E20: QĐ2626/BTNMT | F20: 4 | G20: =+SQRT(D20*F20) -> 2.8284271 | H20: =+'1.1.3 Gas LPG Nhà ăn'!$N$25 -> 6.248381 | I20: =+H20/$H$16 -> #REF! | J20: =G20*I20 -> #REF! | K20: =+J20^2/10^-4 -> #REF!
A21: 1.1.5 | B21: Methanol | C21: Đo theo tần suất lấy mẫu quy định: 01 tháng/ lần | D21: 2 | E21: IPCC 2006 | F21: 1 | G21: =+SQRT(D21*F21) -> 1.4142136 | H21: =+'1.1.4 Methanol'!$F$25 -> 0.275 | I21: =+H21/$H$16 -> #REF! | J21: =G21*I21 -> #REF! | K21: =+J21^2/10^-4 -> #REF!
A22: 1.1.6 | B22: Xăng MCC, PCCC | C22: Tự thống kê (qua hoá đơn, ghi chép) | D22: 3 | E22: QĐ2626/BTNMT | F22: 3 | G22: =+SQRT(D22*F22) -> 3 | H22: =+'1.1.5 Xăng MCC '!$N$25 -> 0.34751889 | I22: =+H22/$H$16 -> #REF! | J22: =G22*I22 -> #REF! | K22: =+J22^2/10^-4 -> #REF!
A23: 1.1.7 | B23: Dầu hỏa | C23: Đo theo tần suất lấy mẫu quy định: 01 tháng/ lần | D23: 2 | E23: QĐ2626/BTNMT | F23: 4 | G23: =+SQRT(D23*F23) -> 2.8284271 | H23: =+'1.1.6 Dầu hỏa'!$O$25 -> 512.57316 | I23: =+H23/$H$16 -> #REF! | J23: =G23*I23 -> #REF! | K23: =+J23^2/10^-4 -> #REF!
A24: 1.1.8 | B24: Nước thủy tinh (Silicate) | C24: Đo theo tần suất lấy mẫu quy định: 01 tháng/ lần | D24: 2 | E24: IPCC 2006 | F24: 1 | G24: =+SQRT(D24*F24) -> 1.4142136 | H24: =+'1.1.7 Nước thủy tinh'!$F$25 -> 1.094552 | I24: =+H24/$H$16 -> #REF! | J24: =G24*I24 -> #REF! | K24: =+J24^2/10^-4 -> #REF!
A25: 1.1.9 | B25: Sơn khuôn BR-750 +sơn thao LOALIDPASTE 94l | C25: Đo theo tần suất lấy mẫu quy định: 01 tháng/ lần | D25: 2 | E25: IPCC 2006 | F25: 1 | G25: =+SQRT(D25*F25) -> 1.4142136 | H25: =+'1.1.8.Sơn lõi khuôn BR-750'!$S$26+'1.1.8. Sơn lõi KOALIDPASTE94i'!$Q$26 -> 9.9407865 | I25: =+H25/$H$16 -> #REF! | J25: =G25*I25 -> #REF! | K25: =+J25^2/10^-4 -> #REF!
A26: 1.1.10 | B26: Sơn khuôn - Sepanol | C26: Đo theo tần suất lấy mẫu quy định: 01 tháng/ lần | D26: 2 | E26: IPCC 2006 | F26: 1 | G26: =+SQRT(D26*F26) -> 1.4142136 | H26: =+#REF! -> #REF! | I26: =+H26/$H$16 -> #REF! | J26: =G26*I26 -> #REF! | K26: =+J26^2/10^-4 -> #REF!
A27: 1.1.11 | B27: Cồn công nghiệp C2H5OH | C27: Đo theo tần suất lấy mẫu quy định: 01 tháng/ lần | D27: 2 | E27: IPCC 2006 | F27: 1 | G27: =+SQRT(D27*F27) -> 1.4142136 | H27: =+'1.1.9 Cồn Công nghiệp'!$G$25 -> 59.016019 | I27: =+H27/$H$16 -> #REF! | J27: =G27*I27 -> #REF! | K27: =+J27^2/10^-4 -> #REF!
A28: 1.1.11 | B28: CO2 cho làm thao | C28: Đo theo tần suất lấy mẫu quy định: 01 tháng/ lần | D28: 2 | E28: IPCC 2006 | F28: 1 | G28: =+SQRT(D28*F28) -> 1.4142136 | H28: =+'1.1.10. CO2 kết dính thao'!$J$22 -> 118.25098 | I28: =+H28/$H$16 -> #REF! | J28: =G28*I28 -> #REF! | K28: =+J28^2/10^-4 -> #REF!
A29: 1.2 | B29: Đốt động off-road (Xe vận chuyển nội bộ trong Nhà máy - Không đăng ký biển kiểm soát)
A30: 1.2.1 | B30: DO xe nâng | C30: Đo theo tần suất lấy mẫu quy định: 01 tháng/ lần | D30: 2 | E30: QĐ2626/BTNMT | F30: 4 | G30: =+SQRT(D30*F30) -> 2.8284271 | H30: =+'1.2.1 DO Xe nângNB Offroad'!$N$25 -> 45.515836 | I30: =+H30/$H$16 -> #REF! | J30: =G30*I30 -> #REF! | K30: =+J30^2/10^-4 -> #REF!
A31: 1.2.2 | B31: Xăng | C31: Đo theo tần suất lấy mẫu quy định: 01 tháng/ lần | D31: 2 | E31: QĐ2626/BTNMT | F31: 4 | G31: =+SQRT(D31*F31) -> 2.8284271 | I31: =+H31/$H$16 -> #REF! | J31: =G31*I31 -> #REF! | K31: =+J31^2/10^-4 -> #REF!
A32: 1.3 | B32: Đốt động on-road (Xe vận tải, vận chuyển ngoài đường - Có đăng ký biển kiểm soát)
A33: 1.3.1 | B33: DO xe vận tải nội bộ + bên ngoài | C33: Đo theo tần suất lấy mẫu quy định: 01 tháng/ lần | D33: 2 | E33: QĐ2626/BTNMT | F33: 4 | G33: =+SQRT(D33*F33) -> 2.8284271 | H33: =+'1.2.2 DOXevậntảiBNOnroad'!$P$25 -> 242.95632 | I33: =+H33/$H$16 -> #REF! | J33: =G33*I33 -> #REF! | K33: =+J33^2/10^-4 -> #REF!
A34: 1.3.2 | B34: Xăng xe vận tải bên ngoài | C34: Đo theo tần suất lấy mẫu quy định: 01 tháng/ lần | D34: 2 | E34: QĐ2626/BTNMT | F34: 4 | G34: =+SQRT(D34*F34) -> 2.8284271 | H34: =+'1.2.3 Xăng Xe Onroad'!$N$25 -> 11.86119 | I34: =+H34/$H$16 -> #REF! | J34: =G34*I34 -> #REF! | K34: =+J34^2/10^-4 -> #REF!
A35: 1.4 | B35: Bình chữa cháy CO2 | C35: Tự thống kê (qua hoá đơn, ghi chép) | D35: 3 | E35: TCVN 7026:2013 | F35: 3 | G35: =+SQRT(D35*F35) -> 3 | H35: =+'1.3.1. Bình chữacháyCO2'!$G$22 -> 0.0074 | I35: =+H35/$H$16 -> #REF! | J35: =G35*I35 -> #REF! | K35: =+J35^2/10^-4 -> #REF!
A36: 1.5 | B36: Môi chất lạnh | C36: Tự thống kê (qua hoá đơn, ghi chép) | D36: 3 | E36: IPCC 2006 & 2019 | F36: 4 | G36: =+SQRT(D36*F36) -> 3.4641016 | H36: =+'1.3.2.Môi chất lạnh'!$T$60 -> 12.59382 | I36: =+H36/$H$16 -> #REF! | J36: =G36*I36 -> #REF! | K36: =+J36^2/10^-4 -> #REF!
A37: 1.6 | B37: Xử lý nước thải tập trung | C37: Đo theo tần suất lấy mẫu quy định: 01 tháng/ lần | D37: 2 | E37: IPCC 2019 | F37: 4 | G37: =+SQRT(D37*F37) -> 2.8284271 | H37: =+'1.3.3 BỂ XỬ LÝ NƯỚC THẢI TT '!$K$25+'1.3.3 BỂ XỬ LÝ NƯỚC THẢI TT '!$Q$44+'1.3.3 BỂ XL NƯỚC THẢI TT'!$J$23 -> 26.604561 | I37: =+H37/$H$16 -> #REF! | J37: =G37*I37 -> #REF! | K37: =+J37^2/10^-4 -> #REF!
A38: 1.7 | B38: Số lượng phân bón sử dụng cho cây | C38: Tự thống kê (qua ghi chép) | D38: 3 | E38: IPCC 2019 | F38: 6 | G38: =+SQRT(D38*F38) -> 4.2426407 | H38: =+'1.3.4 Phân bón'!$H$26 -> 0.05577 | I38: =+H38/$H$16 -> #REF! | J38: =G38*I38 -> #REF! | K38: =+J38^2/10^-4 -> #REF!
A39: Cat 2 | B39: Phát thải gián tiếp từ năng lượng nhập khẩu
A40: 2.1 | B40: Điện năng mua từ lưới điện EVN sử dụng tại DISOCO | C40: Đo liên tục thông qua các thiết bị đo lường phù hợp | D40: 1 | E40: 1726/BĐKH-PTCBT | F40: 3 | G40: =+SQRT(D40*F40) -> 1.7320508 | H40: =+'2.1. MUA ĐIỆN NGOÀI '!$H$23 -> 15779.5 | I40: =+H40/$H$41 -> 1 | J40: =G40*I40 -> 1.7320508 | K40: =+J40^2/10^-4 -> 30000
A41: TỔNG CỘNG (tấn CO2e) | H41: =+H40 -> 15779.5 | I41: =+I40 -> 1
A42: Độ không đảm bảo Cat 2 U_total_Cat 2 | K42: =10^-2*SQRT(SUM(K40)) -> 1.7320508
...

Sheet QT03BM02.Độkhôngđảmbảo 1.2 
B1: BẢNG TÍNH TOÁN ĐỘ KHÔNG ĐẢM BẢO TỪNG NGUỒN PHÁT THẢI KHÍ NHÀ KÍNH NĂM: 2024 | I1: QT03/BM.02
A3: Cấp chính xác theo Phương pháp thống kê số liệu (M) | F3: Cấp chính xác của hệ số phát thải (F)
A4: Cách thức Method | C4: Điểm Point | F4: Cách thức Method | J4: Điểm Point
A5: Đo liên tục thông qua các thiết bị đo lường phù hợp Continuous measurement through suitable measuring devices | C5: 1 | F5: Hệ số phát thải từ phép đo lường hoặc tính toán cân bằng vật chất Direct measurement / calculation is not based on emission factor | J5: 1
A6: Đo theo tần suất lấy mẫu quy định (Ví dụ: 1 lần/ tháng,…) Measured according to the specified sampling frequency (e.g., once a month, ...). | C6: 2 | F6: Hệ số phát thải từ dữ liệu được cung cấp từ nhà cung cấp bên ngoài cho công ty Emission factor from data provided by an external supplier to the company (published). | J6: 2
F7: Hệ số phát thải có điều chỉnh theo đặc thù của ngành được công bố. Emission factor by industry characteristics (published). | J7: 3
A8: Tự thống kê (qua hoá đơn, ghi chép) Statistically (through invoices, notes) | C8: 3 | F8: Hệ số phát thải có điều chỉnh theo đặc thù của Quốc gia The emission factor is adjusted according to the characteristics of the country | J8: 4
A9: Ước lượng/ Tính toán Estimates | C9: 4 | F9: Hệ số phát thải theo khu vực được công bố. Emission factor by region (published). | J9: 5
F10: Hệ số phát thải theo Quốc tế (IPCC) International emission factor (IPCC) | J10: 6
A12: Mã Nguồn Source Code | B12: Nguồn Source | C12: Phương pháp thống kê số liệu Statistical methods | D12: Điểm (M) Point (M) | E12: Loại hệ số phát thải Type of emission factor | F12: Điểm (F) Point | G12: Điểm cấp chính xác Point accuracy level Ui | H12: Lượng phát thải CO2e | I12: Tỷ lệ % GHG theo nguồn Ratio % GHG by source xi | J12: Quy đổi Convert Ui*xi | K12: Quy đổi Convert (10^-4)*(Ui*xi)^2
A13: Cat 1 | B13: Phát thải trực tiếp
A14: Độ không đảm bảo Cat 1 U_total_Cat 1 | K14: =10^-2*SQRT(SUM(K18:K37)) -> 1.4506203
A15: Cấp chính xác của bảng số liệu The correct level of the data table | K15: =IF(K14>4,"Level E",IF(K14>3,"Level D",IF(K14>2,"Level C",IF(K14>1,"Level B","Level A")))) -> Level B
A16: TỔNG CỘNG (tấn CO2e) | H16: =+SUM(H18:H37) -> 1126.267 | I16: =+SUM(I18:I37) -> 1
A17: 1.1 | B17: Đốt tĩnh
A18: 1.1.1 | B18: DO máy phát điện | C18: Tự thống kê (qua hoá đơn, ghi chép) | D18: 3 | E18: QĐ2626/BTNMT | F18: 4 | G18: =+SQRT(D18*F18) -> 3.4641016 | H18: =+'1.1.1 DO Máy phát điện'!$N$25 -> 0.95802776 | I18: =+H18/$H$16 -> 0.00085062223 | J18: =G18*I18 -> 0.0029466418 | K18: =+J18^2/10^-4 -> 0.086826981
A19: 1.1.2 | B19: LPG sản xuất | C19: Đo theo tần suất lấy mẫu quy định: 01 tháng/ lần | D19: 2 | E19: QĐ2626/BTNMT | F19: 4 | G19: =+SQRT(D19*F19) -> 2.8284271 | H19: =+'1.1.2 Gas LPG SX'!$N$25 -> 83.522361 | I19: =+H19/$H$16 -> 0.074158578 | J19: =G19*I19 -> 0.20975213 | K19: =+J19^2/10^-4 -> 439.95958
A20: 1.1.3 | B20: LPG nhà bếp | C20: Đo theo tần suất lấy mẫu quy định: 01 tháng/ lần | D20: 2 | E20: QĐ2626/BTNMT | F20: 4 | G20: =+SQRT(D20*F20) -> 2.8284271 | H20: =+'1.1.3 Gas LPG Nhà ăn'!$N$25 -> 6.248381 | I20: =+H20/$H$16 -> 0.0055478682 | J20: =G20*I20 -> 0.015691741 | K20: =+J20^2/10^-4 -> 2.4623074
A21: 1.1.4 | B21: Methanol | C21: Đo theo tần suất lấy mẫu quy định: 01 tháng/ lần | D21: 2 | E21: IPCC 2006 | F21: 1 | G21: =+SQRT(D21*F21) -> 1.4142136 | H21: =+'1.1.4 Methanol'!$F$25 -> 0.275 | I21: =+H21/$H$16 -> 0.00024416945 | J21: =G21*I21 -> 0.00034530775 | K21: =+J21^2/10^-4 -> 0.0011923744
A22: 1.1.5 | B22: Xăng máy cắt cỏ | C22: Tự thống kê (qua hoá đơn, ghi chép) | D22: 3 | E22: QĐ2626/BTNMT | F22: 3 | G22: =+SQRT(D22*F22) -> 3 | H22: =+'1.1.5 Xăng MCC '!$N$25 -> 0.34751889 | I22: =+H22/$H$16 -> 0.00030855817 | J22: =G22*I22 -> 0.0009256745 | K22: =+J22^2/10^-4 -> 0.0085687328
A23: 1.1.6 | B23: Dầu hỏa (Kerosene-Oil) | C23: Đo theo tần suất lấy mẫu quy định: 01 tháng/ lần | D23: 2 | E23: QĐ2626/BTNMT | F23: 4 | G23: =+SQRT(D23*F23) -> 2.8284271 | H23: =+'1.1.6 Dầu hỏa'!$O$25 -> 512.57316 | I23: =+H23/$H$16 -> 0.45510802 | J23: =G23*I23 -> 1.2872399 | K23: =+J23^2/10^-4 -> 16569.865
A24: 1.1.7 | B24: Nước thủy tinh (Silicate) | C24: Đo theo tần suất lấy mẫu quy định: 01 tháng/ lần | D24: 2 | E24: IPCC 2006 | F24: 1 | G24: =+SQRT(D24*F24) -> 1.4142136 | H24: =+'1.1.7 Nước thủy tinh'!$F$25 -> 1.094552 | I24: =+H24/$H$16 -> 0.00097184059 | J24: =G24*I24 -> 0.0013743901 | K24: =+J24^2/10^-4 -> 0.018889483
A25: 1.1.8 | B25: Sơn lõi khuôn (BR-750 và Koalid Paste 94I) | C25: Đo theo tần suất lấy mẫu quy định: 01 tháng/ lần | D25: 2 | E25: IPCC 2006 | F25: 1 | G25: =+SQRT(D25*F25) -> 1.4142136 | H25: =+'1.1.8.Sơn lõi khuôn BR-750'!$S$26+'1.1.8. Sơn lõi KOALIDPASTE94i'!$Q$26 -> 9.9407865 | I25: =+H25/$H$16 -> 0.0088263141 | J25: =G25*I25 -> 0.012482293 | K25: =+J25^2/10^-4 -> 1.5580764
A26: 1.1.9 | B26: Cồn công nghiệp C2H5OH | C26: Đo theo tần suất lấy mẫu quy định: 01 tháng/ lần | D26: 2 | E26: IPCC 2006 | F26: 1 | G26: =+SQRT(D26*F26) -> 1.4142136 | H26: =+'1.1.9 Cồn Công nghiệp'!$G$25 -> 59.016019 | I26: =+H26/$H$16 -> 0.052399669 | J26: =G26*I26 -> 0.074104323 | K26: =+J26^2/10^-4 -> 54.914507
A27: 1.1.10 | B27: CO2 sử dụng cho kết dính thao (core mold) | C27: Đo theo tần suất lấy mẫu quy định: 01 tháng/ lần | D27: 2 | E27: IPCC 2006 | F27: 1 | G27: =+SQRT(D27*F27) -> 1.4142136 | H27: =+'1.1.10. CO2 kết dính thao'!$J$22 -> 118.25098 | I27: =+H27/$H$16 -> 0.10499374 | J27: =G27*I27 -> 0.14848357 | K27: =+J27^2/10^-4 -> 220.4737
A28: 1.2 | B28: Đốt trong di động
A29: 1.2.1 | B29: DO dùng cho xe nâng | C29: Đo theo tần suất lấy mẫu quy định: 01 tháng/ lần | D29: 2 | E29: QĐ2626/BTNMT | F29: 4 | G29: =+SQRT(D29*F29) -> 2.8284271 | H29: =+'1.2.1 DO Xe nângNB Offroad'!$N$25 -> 45.515836 | I29: =+H29/$H$16 -> 0.040413006 | J29: =G29*I29 -> 0.11430524 | K29: =+J29^2/10^-4 -> 130.65688
A30: 1.2.2 | B30: Xăng | C30: Đo theo tần suất lấy mẫu quy định: 01 tháng/ lần | D30: 2 | E30: QĐ2626/BTNMT | F30: 4 | G30: =+SQRT(D30*F30) -> 2.8284271 | I30: =+H30/$H$16 -> 0 | J30: =G30*I30 -> 0 | K30: =+J30^2/10^-4 -> 0
A31: 1.2.2 | B31: DO dùng cho xe tải và xe car chở CBCNV | C31: Đo theo tần suất lấy mẫu quy định: 01 tháng/ lần | D31: 2 | E31: QĐ2626/BTNMT | F31: 4 | G31: =+SQRT(D31*F31) -> 2.8284271 | H31: ='1.2.2 DOXevậntảiBNOnroad'!N25 -> 237.40165 | I31: =+H31/$H$16 -> 0.2107863 | J31: =G31*I31 -> 0.59619368 | K31: =+J31^2/10^-4 -> 3554.4691
A32: 1.2.3 | B32: Xăng dùng cho xe 7 chỗ | C32: Đo theo tần suất lấy mẫu quy định: 01 tháng/ lần | D32: 2 | E32: QĐ2626/BTNMT | F32: 4 | G32: =+SQRT(D32*F32) -> 2.8284271 | H32: =+'1.2.3 Xăng Xe Onroad'!$N$25 -> 11.86119 | I32: =+H32/$H$16 -> 0.01053142 | J32: =G32*I32 -> 0.029787353 | K32: =+J32^2/10^-4 -> 8.8728638
A33: 1.3 | B33: Phát thải rò rỉ
A34: 1.3.1 | B34: CO2 sử dụng cho bình cứu hỏa, diễn tập PCCC | C34: Tự thống kê (qua hoá đơn, ghi chép) | D34: 3 | E34: TCVN 7026:2013 | F34: 3 | G34: =+SQRT(D34*F34) -> 3 | H34: =+'1.3.1. Bình chữacháyCO2'!$G$22 -> 0.0074 | I34: =+H34/$H$16 -> 6.570378e-06 | J34: =G34*I34 -> 1.9711134e-05 | K34: =+J34^2/10^-4 -> 3.885288e-06
A35: 1.3.2 | B35: Môi chất lạnh | C35: Tự thống kê (qua hoá đơn, ghi chép) | D35: 3 | E35: IPCC 2006 & 2019 | F35: 4 | G35: =+SQRT(D35*F35) -> 3.4641016 | H35: =+'1.3.2.Môi chất lạnh'!$T$60 -> 12.59382 | I35: =+H35/$H$16 -> 0.011181913 | J35: =G35*I35 -> 0.038735283 | K35: =+J35^2/10^-4 -> 15.004222
A36: 1.3.3 | B36: Xử lý nước thải tập trung | C36: Đo theo tần suất lấy mẫu quy định: 01 tháng/ lần | D36: 2 | E36: IPCC 2019 | F36: 4 | G36: =+SQRT(D36*F36) -> 2.8284271 | H36: =+'1.3.3 BỂ XỬ LÝ NƯỚC THẢI TT '!$K$25+'1.3.3 BỂ XỬ LÝ NƯỚC THẢI TT '!$Q$44+'1.3.3 BỂ XL NƯỚC THẢI TT'!$J$23 -> 26.604561 | I36: =+H36/$H$16 -> 0.023621894 | J36: =G36*I36 -> 0.066812807 | K36: =+J36^2/10^-4 -> 44.639511
A37: 1.3.4 | B37: Số lượng phân bón sử dụng cho cây | C37: Tự thống kê (qua ghi chép) | D37: 3 | E37: IPCC 2019 | F37: 6 | G37: =+SQRT(D37*F37) -> 4.2426407 | H37: =+'1.3.4 Phân bón'!$H$26 -> 0.05577 | I37: =+H37/$H$16 -> 4.9517565e-05 | J37: =G37*I37 -> 0.00021008523 | K37: =+J37^2/10^-4 -> 0.00044135806
A38: Cat 2 | B38: Phát thải gián tiếp từ năng lượng nhập khẩu
A39: 2.1 | B39: Điện năng mua từ lưới điện EVN sử dụng | C39: Đo liên tục thông qua các thiết bị đo lường phù hợp | D39: 1 | E39: 1726/BĐKH-PTCBT | F39: 3 | G39: =+SQRT(D39*F39) -> 1.7320508 | H39: =+'2.1. MUA ĐIỆN NGOÀI '!$H$23 -> 15779.5 | I39: =+H39/$H$40 -> 1 | J39: =G39*I39 -> 1.7320508 | K39: =+J39^2/10^-4 -> 30000
A40: TỔNG CỘNG (tấn CO2e) | H40: =+H39 -> 15779.5 | I40: =+I39 -> 1
A41: Độ không đảm bảo Cat 2 U_total_Cat 2 | K41: =10^-2*SQRT(SUM(K39)) -> 1.7320508
A42: Cấp chính xác của bảng số liệu The correct level of the data table | K42: =IF(K41>4,"Level E",IF(K41>3,"Level D",IF(K41>2,"Level C",IF(K41>1,"Level B","Level A")))) -> Level B
...

Sheet QT02BM01Bảng địnhluongLoaiKhí..
C1: BẢNG ĐỊNH LƯỢNG KHÍ NHÀ KÍNH TỔNG HỢP NĂM: 2024 | G1: PHỤ LỤC 6 GHG/QT02/BM01
A3: Scopes and categories | C3: Metric tons CO2e | G3: Total (tons CO2 eq.) | H3: Ratio (%)
A4: Cat 1 | B4: Phát thải và loại bỏ KNK trực tiếp. | C4: CO2 | D4: CH4 | E4: N2O | F4: HFCs | G4: =+SUM(G7:G28) -> #REF! | H4: =G4/$G$31*100 -> #REF!
B5: Tổng phát thải | C5: =+SUM(C8:C18)+C20+SUM(C23:C28) -> #REF! | D5: =+SUM(D8:D18)+D20+SUM(D23:D28) -> #REF! | E5: =+SUM(E8:E18)+E20+SUM(E23:E28) -> #REF! | F5: =+SUM(F8:F18)+F20+SUM(F23:F28) -> 12.59382
B6: Tỉ lệ phát thải (%) | C6: =+C5/$G$4 -> #REF! | D6: =+D5/$G$4 -> #REF! | E6: =+E5/$G$4 -> #REF! | F6: =+F5/$G$4 -> #REF!
A7: 1.1 | B7: Đốt tĩnh | C7: =+C8+C9+C11+C13+C14+C15+C16+C18+C17 -> #REF! | D7: =+D8+D9+D11+D13+D14+D15+D16+D18+D17 -> 0.63262421 | E7: =+E8+E9+E11+E13+E14+E15+E16+E18+E17 -> 1.2019347
